Workbook

Sheet 1. Настройки
A1: НАСТРОЙКИ — меняй только жёлтые ячейки, всё пересчитается само
A2: Синим шрифтом на жёлтом фоне = твои цифры. Чёрным = формулы, их не трогай.
A4: Параметр | B4: Значение | C4: Комментарий
A5: Курс: IDR за $1 | B5: 16000 | C5: Проверь перед пересчётом. Все билеты собраны в рупиях.
A6: Водитель: $ за день до 10 часов | B6: 36 | C6: Твоя договорённость. Это за МАШИНУ, не за человека.
A7: Водитель: $ за час переработки | B7: 5 | C7: Рынок 50–100k IDR/час. Уточни у водителя.
A8: Вода, снеки, мелочь — $ на человека | B8: 1.5 | C8: Бутылка воды + запас на мелкие сборы.
A9: Наценка (множитель на себестоимость) | B9: 1.6 | C9: 1.60 = цена в 1.6 раза выше себестоимости (маржа ~37%).
A10: Комиссия за приём платежа, % | B10: 3 | C10: Stripe/PayPal. Уже учтена в себестоимости.
A12: ГЛАВНОЕ, ЧТО НАДО ПОНЯТЬ ПРО ЭТУ МАТЕМАТИКУ
A13: Водитель — фиксированная стоимость на машину. Билеты — переменная, на каждого человека.
A14: Поэтому цена за 1 человека падает с ростом группы, но не так сильно, как кажется:
A15: на 4 человеках билеты это ~70% себестоимости, и они не делятся.
A17: «From $X» на сайте = цена за 1 человека, когда едут 4. Это самая низкая цифра в лестнице.
A18: Она законно называется «from», потому что это реальная цена при полной машине.
A20: ВАЖНО: если пишешь «From $X», рядом обязательно покажи всю лестницу цен (1/2/3/4).
A21: Иначе человек увидит $49, напишет тебе, услышит $71 за двоих — и уйдёт. Это тот самый
A22: развод, от которого ты хочешь отстроиться. Прозрачная лестница = твоё преимущество.

Sheet 2. Билеты по остановкам
A1: ВХОДНЫЕ БИЛЕТЫ ПО КАЖДОЙ ОСТАНОВКЕ — 1 взрослый иностранец, 2026
A2: Маршруты взяты с твоих же страниц туров (блок «Key stops»). Цены — открытые источники 2026, см. лист 5.
A4: Тур | B4: Остановка | C4: IDR с человека | D4: $ с человека | E4: Тип
A5: Ubud Highlights Tour | B5: Batubulan / Celuk / Mas (ремесленные деревни) | C5: 0 | D5: =C5/'1. Настройки'!$B$5 -> 0 | E5: билет
A6: Ubud Highlights Tour | B6: Batuan Temple | C6: 50000 | D6: =C6/'1. Настройки'!$B$5 -> 3.125 | E6: билет
A7: Ubud Highlights Tour | B7: Pura Gunung Kawi Sebatu (вкл. саронг) | C7: 50000 | D7: =C7/'1. Настройки'!$B$5 -> 3.125 | E7: билет
A8: Ubud Highlights Tour | B8: Gunung Kawi (Tampaksiring) | C8: 50000 | D8: =C8/'1. Настройки'!$B$5 -> 3.125 | E8: билет
A9: Ubud Highlights Tour | B9: Kintamani — сбор с иностранца | C9: 50000 | D9: =C9/'1. Настройки'!$B$5 -> 3.125 | E9: билет
A10: Ubud Highlights Tour | B10: Tegalalang Rice Terrace | C10: 20000 | D10: =C10/'1. Настройки'!$B$5 -> 1.25 | E10: билет
A11: Ubud Highlights Tour | B11: Кофейная плантация (дегустация) | C11: 0 | D11: =C11/'1. Настройки'!$B$5 -> 0 | E11: билет
A12: Ubud Highlights Tour | B12: Ubud Monkey Forest | C12: 130000 | D12: =C12/'1. Настройки'!$B$5 -> 8.125 | E12: билет
A13: Ubud Highlights Tour | B13: Ubud Palace | C13: 0 | D13: =C13/'1. Настройки'!$B$5 -> 0 | E13: билет
A14: Ubud Highlights Tour | B14: Парковки за день | C14: 20000 | D14: =C14/'1. Настройки'!$B$5 -> 1.25 | E14: билет
A15: Ubud Highlights Tour | B15: Обед-буфет в Кинтамани (включён в тур) | C15: 125000 | D15: =C15/'1. Настройки'!$B$5 -> 7.8125 | E15: доп
A16: Ubud Instagram Tour | B16: Lempuyang — билет | C16: 100000 | D16: =C16/'1. Настройки'!$B$5 -> 6.25 | E16: билет
... A56: Private Car with Driver (без билетов) | B56: Билетов нет — клиент платит вход сам | C56: 0 | D56: =C56/'1. Настройки'!$B$5 -> 0 | E56: билет
A58: «билет» = вход/парковка, платится всегда. «доп» = обед, лодка, качели — включено в тур по твоему же описанию.
A59: Оранжевым подсвечены «доп» — это то, что часто забывают заложить в цену.

Sheet 3. Цена на 1-2-3-4 чел
A1: СЕБЕСТОИМОСТЬ И ЦЕНА ПО КОЛИЧЕСТВУ ЧЕЛОВЕК
A2: Строка «4» — это и есть твой «From $X» для сайта. Зелёным подсвечена.
A4: Тур | B4: Людей в машине | C4: Водитель $ на 1 чел | D4: Билеты $ на 1 чел | E4: Доп (обед/ лодка/качели) | F4: Вода, мелочь | G4: СЕБЕСТОИМОСТЬ $ на 1 чел | H4: Себестоимость всего выезда | I4: ЦЕНА КЛИЕНТУ $ на 1 чел | J4: Прибыль $ на 1 чел | K4: Прибыль с выезда | L4: Маржа %
A5: Ubud Highlights Tour | B5: 1 | C5: =('1. Настройки'!$B$6+0*'1. Настройки'!$B$7)/B5 -> 36 | D5: =SUMIFS('2. Билеты по остановкам'!$D$5:$D$56,'2. Билеты по остановкам'!$A$5:$A$56,$A$5,'2. Билеты по остановкам'!$E$5:$E$56,"билет") -> 23.125 | E5: =SUMIFS('2. Билеты по остановкам'!$D$5:$D$56,'2. Билеты по остановкам'!$A$5:$A$56,$A$5,'2. Билеты по остановкам'!$E$5:$E$56,"доп") -> 7.8125 | F5: ='1. Настройки'!$B$8 -> 1.5 | G5: =(C5+D5+E5+F5)*(1+'1. Настройки'!$B$10/100) -> 70.490625 | H5: =G5*B5 -> 70.490625 | I5: =CEILING(G5*'1. Настройки'!$B$9+1,5)-1 -> 114 | J5: =I5-G5 -> 43.509375 | K5: =J5*B5 -> 43.509375 | L5: =IFERROR(J5/I5,0) -> 0.38166118
B6: 2 | C6: =('1. Настройки'!$B$6+0*'1. Настройки'!$B$7)/B6 -> 18 | D6: =SUMIFS('2. Билеты по остановкам'!$D$5:$D$56,'2. Билеты по остановкам'!$A$5:$A$56,$A$5,'2. Билеты по остановкам'!$E$5:$E$56,"билет") -> 23.125 | E6: =SUMIFS('2. Билеты по остановкам'!$D$5:$D$56,'2. Билеты по остановкам'!$A$5:$A$56,$A$5,'2. Билеты по остановкам'!$E$5:$E$56,"доп") -> 7.8125 | F6: ='1. Настройки'!$B$8 -> 1.5 | G6: =(C6+D6+E6+F6)*(1+'1. Настройки'!$B$10/100) -> 51.950625 | H6: =G6*B6 -> 103.90125 | I6: =CEILING(G6*'1. Настройки'!$B$9+1,5)-1 -> 84 | J6: =I6-G6 -> 32.049375 | K6: =J6*B6 -> 64.09875 | L6: =IFERROR(J6/I6,0) -> 0.38154018
B7: 3 | C7: =('1. Настройки'!$B$6+0*'1. Настройки'!$B$7)/B7 -> 12 | D7: =SUMIFS('2. Билеты по остановкам'!$D$5:$D$56,'2. Билеты по остановкам'!$A$5:$A$56,$A$5,'2. Билеты по остановкам'!$E$5:$E$56,"билет") -> 23.125 | E7: =SUMIFS('2. Билеты по остановкам'!$D$5:$D$56,'2. Билеты по остановкам'!$A$5:$A$56,$A$5,'2. Билеты по остановкам'!$E$5:$E$56,"доп") -> 7.8125 | F7: ='1. Настройки'!$B$8 -> 1.5 | G7: =(C7+D7+E7+F7)*(1+'1. Настройки'!$B$10/100) -> 45.770625 | H7: =G7*B7 -> 137.31187 | I7: =CEILING(G7*'1. Настройки'!$B$9+1,5)-1 -> 74 | J7: =I7-G7 -> 28.229375 | K7: =J7*B7 -> 84.688125 | L7: =IFERROR(J7/I7,0) -> 0.38147804
B8: 4 | C8: =('1. Настройки'!$B$6+0*'1. Настройки'!$B$7)/B8 -> 9 | D8: =SUMIFS('2. Билеты по остановкам'!$D$5:$D$56,'2. Билеты по остановкам'!$A$5:$A$56,$A$5,'2. Билеты по остановкам'!$E$5:$E$56,"билет") -> 23.125 | E8: =SUMIFS('2. Билеты по остановкам'!$D$5:$D$56,'2. Билеты по остановкам'!$A$5:$A$56,$A$5,'2. Билеты по остановкам'!$E$5:$E$56,"доп") -> 7.8125 | F8: ='1. Настройки'!$B$8 -> 1.5 | G8: =(C8+D8+E8+F8)*(1+'1. Настройки'!$B$10/100) -> 42.680625 | H8: =G8*B8 -> 170.7225 | I8: =CEILING(G8*'1. Настройки'!$B$9+1,5)-1 -> 69 | J8: =I8-G8 -> 26.319375 | K8: =J8*B8 -> 105.2775 | L8: =IFERROR(J8/I8,0) -> 0.38144022
A10: Ubud Instagram Tour | B10: 1 | C10: =('1. Настройки'!$B$6+0*'1. Настройки'!$B$7)/B10 -> 36 | D10: =SUMIFS('2. Билеты по остановкам'!$D$5:$D$56,'2. Билеты по остановкам'!$A$5:$A$56,$A$10,'2. Билеты по остановкам'!$E$5:$E$56,"билет") -> 19.6875 | E10: =SUMIFS('2. Билеты по остановкам'!$D$5:$D$56,'2. Билеты по остановкам'!$A$5:$A$56,$A$10,'2. Билеты по остановкам'!$E$5:$E$56,"доп") -> 21.875 | F10: ='1. Настройки'!$B$8 -> 1.5 | G10: =(C10+D10+E10+F10)*(1+'1. Настройки'!$B$10/100) -> 81.434375 | H10: =G10*B10 -> 81.434375 | I10: =CEILING(G10*'1. Настройки'!$B$9+1,5)-1 -> 134 | J10: =I10-G10 -> 52.565625 | K10: =J10*B10 -> 52.565625 | L10: =IFERROR(J10/I10,0) -> 0.39228078
B11: 2 | C11: =('1. Настройки'!$B$6+0*'1. Настройки'!$B$7)/B11 -> 18 | D11: =SUMIFS('2. Билеты по остановкам'!$D$5:$D$56,'2. Билеты по остановкам'!$A$5:$A$56,$A$10,'2. Билеты по остановкам'!$E$5:$E$56,"билет") -> 19.6875 | E11: =SUMIFS('2. Билеты по остановкам'!$D$5:$D$56,'2. Билеты по остановкам'!$A$5:$A$56,$A$10,'2. Билеты по остановкам'!$E$5:$E$56,"доп") -> 21.875 | F11: ='1. Настройки'!$B$8 -> 1.5 | G11: =(C11+D11+E11+F11)*(1+'1. Настройки'!$B$10/100) -> 62.894375 | H11: =G11*B11 -> 125.78875 | I11: =CEILING(G11*'1. Настройки'!$B$9+1,5)-1 -> 104 | J11: =I11-G11 -> 41.105625 | K11: =J11*B11 -> 82.21125 | L11: =IFERROR(J11/I11,0) -> 0.39524639
B12: 3 | C12: =('1. Настройки'!$B$6+0*'1. Настройки'!$B$7)/B12 -> 12 | D12: =SUMIFS('2. Билеты по остановкам'!$D$5:$D$56,'2. Билеты по остановкам'!$A$5:$A$56,$A$10,'2. Билеты по остановкам'!$E$5:$E$56,"билет") -> 19.6875 | E12: =SUMIFS('2. Билеты по остановкам'!$D$5:$D$56,'2. Билеты по остановкам'!$A$5:$A$56,$A$10,'2. Билеты по остановкам'!$E$5:$E$56,"доп") -> 21.875 | F12: ='1. Настройки'!$B$8 -> 1.5 | G12: =(C12+D12+E12+F12)*(1+'1. Настройки'!$B$10/100) -> 56.714375 | H12: =G12*B12 -> 170.14312 | I12: =CEILING(G12*'1. Настройки'!$B$9+1,5)-1 -> 94 | J12: =I12-G12 -> 37.285625 | K12: =J12*B12 -> 111.85688 | L12: =IFERROR(J12/I12,0) -> 0.39665559
B13: 4 | C13: =('1. Настройки'!$B$6+0*'1. Настройки'!$B$7)/B13 -> 9 | D13: =SUMIFS('2. Билеты по остановкам'!$D$5:$D$56,'2. Билеты по остановкам'!$A$5:$A$56,$A$10,'2. Билеты по остановкам'!$E$5:$E$56,"билет") -> 19.6875 | E13: =SUMIFS('2. Билеты по остановкам'!$D$5:$D$56,'2. Билеты по остановкам'!$A$5:$A$56,$A$10,'2. Билеты по остановкам'!$E$5:$E$56,"доп") -> 21.875 | F13: ='1. Настройки'!$B$8 -> 1.5 | G13: =(C13+D13+E13+F13)*(1+'1. Настройки'!$B$10/100) -> 53.624375 | H13: =G13*B13 -> 214.4975 | I13: =CEILING(G13*'1. Настройки'!$B$9+1,5)-1 -> 89 | J13: =I13-G13 -> 35.375625 | K13: =J13*B13 -> 141.5025 | L13: =IFERROR(J13/I13,0) -> 0.39747893
A15: Bali UNESCO Heritage Tour | B15: 1 | C15: =('1. Настройки'!$B$6+0*'1. Настройки'!$B$7)/B15 -> 36 | D15: =SUMIFS('2. Билеты по остановкам'!$D$5:$D$56,'2. Билеты по остановкам'!$A$5:$A$56,$A$15,'2. Билеты по остановкам'!$E$5:$E$56,"билет") -> 23.125 | E15: =SUMIFS('2. Билеты по остановкам'!$D$5:$D$56,'2. Билеты по остановкам'!$A$5:$A$56,$A$15,'2. Билеты по остановкам'!$E$5:$E$56,"доп") -> 0 | F15: ='1. Настройки'!$B$8 -> 1.5 | G15: =(C15+D15+E15+F15)*(1+'1. Настройки'!$B$10/100) -> 62.44375 | H15: =G15*B15 -> 62.44375 | I15: =CEILING(G15*'1. Настройки'!$B$9+1,5)-1 -> 104 | J15: =I15-G15 -> 41.55625 | K15: =J15*B15 -> 41.55625 | L15: =IFERROR(J15/I15,0) -> 0.39957933
B16: 2 | C16: =('1. Настройки'!$B$6+0*'1. Настройки'!$B$7)/B16 -> 18 | D16: =SUMIFS('2. Билеты по остановкам'!$D$5:$D$56,'2. Билеты по остановкам'!$A$5:$A$56,$A$15,'2. Билеты по остановкам'!$E$5:$E$56,"билет") -> 23.125 | E16: =SUMIFS('2. Билеты по остановкам'!$D$5:$D$56,'2. Билеты по остановкам'!$A$5:$A$56,$A$15,'2. Билеты по остановкам'!$E$5:$E$56,"доп") -> 0 | F16: ='1. Настройки'!$B$8 -> 1.5 | G16: =(C16+D16+E16+F16)*(1+'1. Настройки'!$B$10/100) -> 43.90375 | H16: =G16*B16 -> 87.8075 | I16: =CEILING(G16*'1. Настройки'!$B$9+1,5)-1 -> 74 | J16: =I16-G16 -> 30.09625 | K16: =J16*B16 -> 60.1925 | L16: =IFERROR(J16/I16,0) -> 0.40670608
B17: 3 | C17: =('1. Настройки'!$B$6+0*'1. Настройки'!$B$7)/B17 -> 12 | D17: =SUMIFS('2. Билеты по остановкам'!$D$5:$D$56,'2. Билеты по остановкам'!$A$5:$A$56,$A$15,'2. Билеты по остановкам'!$E$5:$E$56,"билет") -> 23.125 | E17: =SUMIFS('2. Билеты по остановкам'!$D$5:$D$56,'2. Билеты по остановкам'!$A$5:$A$56,$A$15,'2. Билеты по остановкам'!$E$5:$E$56,"доп") -> 0 | F17: ='1. Настройки'!$B$8 -> 1.5 | G17: =(C17+D17+E17+F17)*(1+'1. Настройки'!$B$10/100) -> 37.72375 | H17: =G17*B17 -> 113.17125 | I17: =CEILING(G17*'1. Настройки'!$B$9+1,5)-1 -> 64 | J17: =I17-G17 -> 26.27625 | K17: =J17*B17 -> 78.82875 | L17: =IFERROR(J17/I17,0) -> 0.41056641
B18: 4 | C18: =('1. Настройки'!$B$6+0*'1. Настройки'!$B$7)/B18 -> 9 | D18: =SUMIFS('2. Билеты по остановкам'!$D$5:$D$56,'2. Билеты по остановкам'!$A$5:$A$56,$A$15,'2. Билеты по остановкам'!$E$5:$E$56,"билет") -> 23.125 | E18: =SUMIFS('2. Билеты по остановкам'!$D$5:$D$56,'2. Билеты по остановкам'!$A$5:$A$56,$A$15,'2. Билеты по остановкам'!$E$5:$E$56,"доп") -> 0 | F18: ='1. Настройки'!$B$8 -> 1.5 | G18: =(C18+D18+E18+F18)*(1+'1. Настройки'!$B$10/100) -> 34.63375 | H18: =G18*B18 -> 138.535 | I18: =CEILING(G18*'1. Настройки'!$B$9+1,5)-1 -> 59 | J18: =I18-G18 -> 24.36625 | K18: =J18*B18 -> 97.465 | L18: =IFERROR(J18/I18,0) -> 0.41298729
A20: Tanah Lot & Bedugul Tour | B20: 1 | C20: =('1. Настройки'!$B$6+0*'1. Настройки'!$B$7)/B20 -> 36 | D20: =SUMIFS('2. Билеты по остановкам'!$D$5:$D$56,'2. Билеты по остановкам'!$A$5:$A$56,$A$20,'2. Билеты по остановкам'!$E$5:$E$56,"билет") -> 23.75 | E20: =SUMIFS('2. Билеты по остановкам'!$D$5:$D$56,'2. Билеты по остановкам'!$A$5:$A$56,$A$20,'2. Билеты по остановкам'!$E$5:$E$56,"доп") -> 0 | F20: ='1. Настройки'!$B$8 -> 1.5 | G20: =(C20+D20+E20+F20)*(1+'1. Настройки'!$B$10/100) -> 63.0875 | H20: =G20*B20 -> 63.0875 | I20: =CEILING(G20*'1. Настройки'!$B$9+1,5)-1 -> 104 | J20: =I20-G20 -> 40.9125 | K20: =J20*B20 -> 40.9125 | L20: =IFERROR(J20/I20,0) -> 0.39338942
B21: 2 | C21: =('1. Настройки'!$B$6+0*'1. Настройки'!$B$7)/B21 -> 18 | D21: =SUMIFS('2. Билеты по остановкам'!$D$5:$D$56,'2. Билеты по остановкам'!$A$5:$A$56,$A$20,'2. Билеты по остановкам'!$E$5:$E$56,"билет") -> 23.75 | E21: =SUMIFS('2. Билеты по остановкам'!$D$5:$D$56,'2. Билеты по остановкам'!$A$5:$A$56,$A$20,'2. Билеты по остановкам'!$E$5:$E$56,"доп") -> 0 | F21: ='1. Настройки'!$B$8 -> 1.5 | G21: =(C21+D21+E21+F21)*(1+'1. Настройки'!$B$10/100) -> 44.5475 | H21: =G21*B21 -> 89.095 | I21: =CEILING(G21*'1. Настройки'!$B$9+1,5)-1 -> 74 | J21: =I21-G21 -> 29.4525 | K21: =J21*B21 -> 58.905 | L21: =IFERROR(J21/I21,0) -> 0.39800676
B22: 3 | C22: =('1. Настройки'!$B$6+0*'1. Настройки'!$B$7)/B22 -> 12 | D22: =SUMIFS('2. Билеты по остановкам'!$D$5:$D$56,'2. Билеты по остановкам'!$A$5:$A$56,$A$20,'2. Билеты по остановкам'!$E$5:$E$56,"билет") -> 23.75 | E22: =SUMIFS('2. Билеты по остановкам'!$D$5:$D$56,'2. Билеты по остановкам'!$A$5:$A$56,$A$20,'2. Билеты по остановкам'!$E$5:$E$56,"доп") -> 0 | F22: ='1. Настройки'!$B$8 -> 1.5 | G22: =(C22+D22+E22+F22)*(1+'1. Настройки'!$B$10/100) -> 38.3675 | H22: =G22*B22 -> 115.1025 | I22: =CEILING(G22*'1. Настройки'!$B$9+1,5)-1 -> 64 | J22: =I22-G22 -> 25.6325 | K22: =J22*B22 -> 76.8975 | L22: =IFERROR(J22/I22,0) -> 0.40050781
B23: 4 | C23: =('1. Настройки'!$B$6+0*'1. Настройки'!$B$7)/B23 -> 9 | D23: =SUMIFS('2. Билеты по остановкам'!$D$5:$D$56,'2. Билеты по остановкам'!$A$5:$A$56,$A$20,'2. Билеты по остановкам'!$E$5:$E$56,"билет") -> 23.75 | E23: =SUMIFS('2. Билеты по остановкам'!$D$5:$D$56,'2. Билеты по остановкам'!$A$5:$A$56,$A$20,'2. Билеты по остановкам'!$E$5:$E$56,"доп") -> 0 | F23: ='1. Настройки'!$B$8 -> 1.5 | G23: =(C23+D23+E23+F23)*(1+'1. Настройки'!$B$10/100) -> 35.2775 | H23: =G23*B23 -> 141.11 | I23: =CEILING(G23*'1. Настройки'!$B$9+1,5)-1 -> 59 | J23: =I23-G23 -> 23.7225 | K23: =J23*B23 -> 94.89 | L23: =IFERROR(J23/I23,0) -> 0.40207627
A25: East Bali Instagram Tour | B25: 1 | C25: =('1. Настройки'!$B$6+0*'1. Настройки'!$B$7)/B25 -> 36 | D25: =SUMIFS('2. Билеты по остановкам'!$D$5:$D$56,'2. Билеты по остановкам'!$A$5:$A$56,$A$25,'2. Билеты по остановкам'!$E$5:$E$56,"билет") -> 27.1875 | E25: =SUMIFS('2. Билеты по остановкам'!$D$5:$D$56,'2. Билеты по остановкам'!$A$5:$A$56,$A$25,'2. Билеты по остановкам'!$E$5:$E$56,"доп") -> 0 | F25: ='1. Настройки'!$B$8 -> 1.5 | G25: =(C25+D25+E25+F25)*(1+'1. Настройки'!$B$10/100) -> 66.628125 | H25: =G25*B25 -> 66.628125 | I25: =CEILING(G25*'1. Настройки'!$B$9+1,5)-1 -> 109 | J25: =I25-G25 -> 42.371875 | K25: =J25*B25 -> 42.371875 | L25: =IFERROR(J25/I25,0) -> 0.3887328
B26: 2 | C26: =('1. Настройки'!$B$6+0*'1. Настройки'!$B$7)/B26 -> 18 | D26: =SUMIFS('2. Билеты по остановкам'!$D$5:$D$56,'2. Билеты по остановкам'!$A$5:$A$56,$A$25,'2. Билеты по остановкам'!$E$5:$E$56,"билет") -> 27.1875 | E26: =SUMIFS('2. Билеты по остановкам'!$D$5:$D$56,'2. Билеты по остановкам'!$A$5:$A$56,$A$25,'2. Билеты по остановкам'!$E$5:$E$56,"доп") -> 0 | F26: ='1. Настройки'!$B$8 -> 1.5 | G26: =(C26+D26+E26+F26)*(1+'1. Настройки'!$B$10/100) -> 48.088125 | H26: =G26*B26 -> 96.17625 | I26: =CEILING(G26*'1. Настройки'!$B$9+1,5)-1 -> 79 | J26: =I26-G26 -> 30.911875 | K26: =J26*B26 -> 61.82375 | L26: =IFERROR(J26/I26,0) -> 0.39128956
B27: 3 | C27: =('1. Настройки'!$B$6+0*'1. Настройки'!$B$7)/B27 -> 12 | D27: =SUMIFS('2. Билеты по остановкам'!$D$5:$D$56,'2. Билеты по остановкам'!$A$5:$A$56,$A$25,'2. Билеты по остановкам'!$E$5:$E$56,"билет") -> 27.1875 | E27: =SUMIFS('2. Билеты по остановкам'!$D$5:$D$56,'2. Билеты по остановкам'!$A$5:$A$56,$A$25,'2. Билеты по остановкам'!$E$5:$E$56,"доп") -> 0 | F27: ='1. Настройки'!$B$8 -> 1.5 | G27: =(C27+D27+E27+F27)*(1+'1. Настройки'!$B$10/100) -> 41.908125 | H27: =G27*B27 -> 125.72437 | I27: =CEILING(G27*'1. Настройки'!$B$9+1,5)-1 -> 69 | J27: =I27-G27 -> 27.091875 | K27: =J27*B27 -> 81.275625 | L27: =IFERROR(J27/I27,0) -> 0.39263587
B28: 4 | C28: =('1. Настройки'!$B$6+0*'1. Настройки'!$B$7)/B28 -> 9 | D28: =SUMIFS('2. Билеты по остановкам'!$D$5:$D$56,'2. Билеты по остановкам'!$A$5:$A$56,$A$25,'2. Билеты по остановкам'!$E$5:$E$56,"билет") -> 27.1875 | E28: =SUMIFS('2. Билеты по остановкам'!$D$5:$D$56,'2. Билеты по остановкам'!$A$5:$A$56,$A$25,'2. Билеты по остановкам'!$E$5:$E$56,"доп") -> 0 | F28: ='1. Настройки'!$B$8 -> 1.5 | G28: =(C28+D28+E28+F28)*(1+'1. Настройки'!$B$10/100) -> 38.818125 | H28: =G28*B28 -> 155.2725 | I28: =CEILING(G28*'1. Настройки'!$B$9+1,5)-1 -> 64 | J28: =I28-G28 -> 25.181875 | K28: =J28*B28 -> 100.7275 | L28: =IFERROR(J28/I28,0) -> 0.3934668
A30: Bali Instagram Highlights Tour | B30: 1 | C30: =('1. Настройки'!$B$6+2*'1. Настройки'!$B$7)/B30 -> 46 | D30: =SUMIFS('2. Билеты по остановкам'!$D$5:$D$56,'2. Билеты по остановкам'!$A$5:$A$56,$A$30,'2. Билеты по остановкам'!$E$5:$E$56,"билет") -> 25.9375 | E30: =SUMIFS('2. Билеты по остановкам'!$D$5:$D$56,'2. Билеты по остановкам'!$A$5:$A$56,$A$30,'2. Билеты по остановкам'!$E$5:$E$56,"доп") -> 0 | F30: ='1. Настройки'!$B$8 -> 1.5 | G30: =(C30+D30+E30+F30)*(1+'1. Настройки'!$B$10/100) -> 75.640625 | H30: =G30*B30 -> 75.640625 | I30: =CEILING(G30*'1. Настройки'!$B$9+1,5)-1 -> 124 | J30: =I30-G30 -> 48.359375 | K30: =J30*B30 -> 48.359375 | L30: =IFERROR(J30/I30,0) -> 0.38999496
B31: 2 | C31: =('1. Настройки'!$B$6+2*'1. Настройки'!$B$7)/B31 -> 23 | D31: =SUMIFS('2. Билеты по остановкам'!$D$5:$D$56,'2. Билеты по остановкам'!$A$5:$A$56,$A$30,'2. Билеты по остановкам'!$E$5:$E$56,"билет") -> 25.9375 | E31: =SUMIFS('2. Билеты по остановкам'!$D$5:$D$56,'2. Билеты по остановкам'!$A$5:$A$56,$A$30,'2. Билеты по остановкам'!$E$5:$E$56,"доп") -> 0 | F31: ='1. Настройки'!$B$8 -> 1.5 | G31: =(C31+D31+E31+F31)*(1+'1. Настройки'!$B$10/100) -> 51.950625 | H31: =G31*B31 -> 103.90125 | I31: =CEILING(G31*'1. Настройки'!$B$9+1,5)-1 -> 84 | J31: =I31-G31 -> 32.049375 | K31: =J31*B31 -> 64.09875 | L31: =IFERROR(J31/I31,0) -> 0.38154018
B32: 3 | C32: =('1. Настройки'!$B$6+2*'1. Настройки'!$B$7)/B32 -> 15.333333 | D32: =SUMIFS('2. Билеты по остановкам'!$D$5:$D$56,'2. Билеты по остановкам'!$A$5:$A$56,$A$30,'2. Билеты по остановкам'!$E$5:$E$56,"билет") -> 25.9375 | E32: =SUMIFS('2. Билеты по остановкам'!$D$5:$D$56,'2. Билеты по остановкам'!$A$5:$A$56,$A$30,'2. Билеты по остановкам'!$E$5:$E$56,"доп") -> 0 | F32: ='1. Настройки'!$B$8 -> 1.5 | G32: =(C32+D32+E32+F32)*(1+'1. Настройки'!$B$10/100) -> 44.053958 | H32: =G32*B32 -> 132.16188 | I32: =CEILING(G32*'1. Настройки'!$B$9+1,5)-1 -> 74 | J32: =I32-G32 -> 29.946042 | K32: =J32*B32 -> 89.838125 | L32: =IFERROR(J32/I32,0) -> 0.40467624
B33: 4 | C33: =('1. Настройки'!$B$6+2*'1. Настройки'!$B$7)/B33 -> 11.5 | D33: =SUMIFS('2. Билеты по остановкам'!$D$5:$D$56,'2. Билеты по остановкам'!$A$5:$A$56,$A$30,'2. Билеты по остановкам'!$E$5:$E$56,"билет") -> 25.9375 | E33: =SUMIFS('2. Билеты по остановкам'!$D$5:$D$56,'2. Билеты по остановкам'!$A$5:$A$56,$A$30,'2. Билеты по остановкам'!$E$5:$E$56,"доп") -> 0 | F33: ='1. Настройки'!$B$8 -> 1.5 | G33: =(C33+D33+E33+F33)*(1+'1. Настройки'!$B$10/100) -> 40.105625 | H33: =G33*B33 -> 160.4225 | I33: =CEILING(G33*'1. Настройки'!$B$9+1,5)-1 -> 69 | J33: =I33-G33 -> 28.894375 | K33: =J33*B33 -> 115.5775 | L33: =IFERROR(J33/I33,0) -> 0.41875906
A35: North Bali & Lovina Dolphins | B35: 1 | C35: =('1. Настройки'!$B$6+2*'1. Настройки'!$B$7)/B35 -> 46 | D35: =SUMIFS('2. Билеты по остановкам'!$D$5:$D$56,'2. Билеты по остановкам'!$A$5:$A$56,$A$35,'2. Билеты по остановкам'!$E$5:$E$56,"билет") -> 7.5 | E35: =SUMIFS('2. Билеты по остановкам'!$D$5:$D$56,'2. Билеты по остановкам'!$A$5:$A$56,$A$35,'2. Билеты по остановкам'!$E$5:$E$56,"доп") -> 6.25 | F35: ='1. Настройки'!$B$8 -> 1.5 | G35: =(C35+D35+E35+F35)*(1+'1. Настройки'!$B$10/100) -> 63.0875 | H35: =G35*B35 -> 63.0875 | I35: =CEILING(G35*'1. Настройки'!$B$9+1,5)-1 -> 104 | J35: =I35-G35 -> 40.9125 | K35: =J35*B35 -> 40.9125 | L35: =IFERROR(J35/I35,0) -> 0.39338942
B36: 2 | C36: =('1. Настройки'!$B$6+2*'1. Настройки'!$B$7)/B36 -> 23 | D36: =SUMIFS('2. Билеты по остановкам'!$D$5:$D$56,'2. Билеты по остановкам'!$A$5:$A$56,$A$35,'2. Билеты по остановкам'!$E$5:$E$56,"билет") -> 7.5 | E36: =SUMIFS('2. Билеты по остановкам'!$D$5:$D$56,'2. Билеты по остановкам'!$A$5:$A$56,$A$35,'2. Билеты по остановкам'!$E$5:$E$56,"доп") -> 6.25 | F36: ='1. Настройки'!$B$8 -> 1.5 | G36: =(C36+D36+E36+F36)*(1+'1. Настройки'!$B$10/100) -> 39.3975 | H36: =G36*B36 -> 78.795 | I36: =CEILING(G36*'1. Настройки'!$B$9+1,5)-1 -> 64 | J36: =I36-G36 -> 24.6025 | K36: =J36*B36 -> 49.205 | L36: =IFERROR(J36/I36,0) -> 0.38441406
B37: 3 | C37: =('1. Настройки'!$B$6+2*'1. Настройки'!$B$7)/B37 -> 15.333333 | D37: =SUMIFS('2. Билеты по остановкам'!$D$5:$D$56,'2. Билеты по остановкам'!$A$5:$A$56,$A$35,'2. Билеты по остановкам'!$E$5:$E$56,"билет") -> 7.5 | E37: =SUMIFS('2. Билеты по остановкам'!$D$5:$D$56,'2. Билеты по остановкам'!$A$5:$A$56,$A$35,'2. Билеты по остановкам'!$E$5:$E$56,"доп") -> 6.25 | F37: ='1. Настройки'!$B$8 -> 1.5 | G37: =(C37+D37+E37+F37)*(1+'1. Настройки'!$B$10/100) -> 31.500833 | H37: =G37*B37 -> 94.5025 | I37: =CEILING(G37*'1. Настройки'!$B$9+1,5)-1 -> 54 | J37: =I37-G37 -> 22.499167 | K37: =J37*B37 -> 67.4975 | L37: =IFERROR(J37/I37,0) -> 0.41665123
B38: 4 | C38: =('1. Настройки'!$B$6+2*'1. Настройки'!$B$7)/B38 -> 11.5 | D38: =SUMIFS('2. Билеты по остановкам'!$D$5:$D$56,'2. Билеты по остановкам'!$A$5:$A$56,$A$35,'2. Билеты по остановкам'!$E$5:$E$56,"билет") -> 7.5 | E38: =SUMIFS('2. Билеты по остановкам'!$D$5:$D$56,'2. Билеты по остановкам'!$A$5:$A$56,$A$35,'2. Билеты по остановкам'!$E$5:$E$56,"доп") -> 6.25 | F38: ='1. Настройки'!$B$8 -> 1.5 | G38: =(C38+D38+E38+F38)*(1+'1. Настройки'!$B$10/100) -> 27.5525 | H38: =G38*B38 -> 110.21 | I38: =CEILING(G38*'1. Настройки'!$B$9+1,5)-1 -> 49 | J38: =I38-G38 -> 21.4475 | K38: =J38*B38 -> 85.79 | L38: =IFERROR(J38/I38,0) -> 0.43770408
A40: Lovina Dolphin Sunrise Tour | B40: 1 | C40: =('1. Настройки'!$B$6+0*'1. Настройки'!$B$7)/B40 -> 36 | D40: =SUMIFS('2. Билеты по остановкам'!$D$5:$D$56,'2. Билеты по остановкам'!$A$5:$A$56,$A$40,'2. Билеты по остановкам'!$E$5:$E$56,"билет") -> 8.75 | E40: =SUMIFS('2. Билеты по остановкам'!$D$5:$D$56,'2. Билеты по остановкам'!$A$5:$A$56,$A$40,'2. Билеты по остановкам'!$E$5:$E$56,"доп") -> 6.25 | F40: ='1. Настройки'!$B$8 -> 1.5 | G40: =(C40+D40+E40+F40)*(1+'1. Настройки'!$B$10/100) -> 54.075 | H40: =G40*B40 -> 54.075 | I40: =CEILING(G40*'1. Настройки'!$B$9+1,5)-1 -> 89 | J40: =I40-G40 -> 34.925 | K40: =J40*B40 -> 34.925 | L40: =IFERROR(J40/I40,0) -> 0.39241573
B41: 2 | C41: =('1. Настройки'!$B$6+0*'1. Настройки'!$B$7)/B41 -> 18 | D41: =SUMIFS('2. Билеты по остановкам'!$D$5:$D$56,'2. Билеты по остановкам'!$A$5:$A$56,$A$40,'2. Билеты по остановкам'!$E$5:$E$56,"билет") -> 8.75 | E41: =SUMIFS('2. Билеты по остановкам'!$D$5:$D$56,'2. Билеты по остановкам'!$A$5:$A$56,$A$40,'2. Билеты по остановкам'!$E$5:$E$56,"доп") -> 6.25 | F41: ='1. Настройки'!$B$8 -> 1.5 | G41: =(C41+D41+E41+F41)*(1+'1. Настройки'!$B$10/100) -> 35.535 | H41: =G41*B41 -> 71.07 | I41: =CEILING(G41*'1. Настройки'!$B$9+1,5)-1 -> 59 | J41: =I41-G41 -> 23.465 | K41: =J41*B41 -> 46.93 | L41: =IFERROR(J41/I41,0) -> 0.39771186
B42: 3 | C42: =('1. Настройки'!$B$6+0*'1. Настройки'!$B$7)/B42 -> 12 | D42: =SUMIFS('2. Билеты по остановкам'!$D$5:$D$56,'2. Билеты по остановкам'!$A$5:$A$56,$A$40,'2. Билеты по остановкам'!$E$5:$E$56,"билет") -> 8.75 | E42: =SUMIFS('2. Билеты по остановкам'!$D$5:$D$56,'2. Билеты по остановкам'!$A$5:$A$56,$A$40,'2. Билеты по остановкам'!$E$5:$E$56,"доп") -> 6.25 | F42: ='1. Настройки'!$B$8 -> 1.5 | G42: =(C42+D42+E42+F42)*(1+'1. Настройки'!$B$10/100) -> 29.355 | H42: =G42*B42 -> 88.065 | I42: =CEILING(G42*'1. Настройки'!$B$9+1,5)-1 -> 49 | J42: =I42-G42 -> 19.645 | K42: =J42*B42 -> 58.935 | L42: =IFERROR(J42/I42,0) -> 0.40091837
B43: 4 | C43: =('1. Настройки'!$B$6+0*'1. Настройки'!$B$7)/B43 -> 9 | D43: =SUMIFS('2. Билеты по остановкам'!$D$5:$D$56,'2. Билеты по остановкам'!$A$5:$A$56,$A$40,'2. Билеты по остановкам'!$E$5:$E$56,"билет") -> 8.75 | E43: =SUMIFS('2. Билеты по остановкам'!$D$5:$D$56,'2. Билеты по остановкам'!$A$5:$A$56,$A$40,'2. Билеты по остановкам'!$E$5:$E$56,"доп") -> 6.25 | F43: ='1. Настройки'!$B$8 -> 1.5 | G43: =(C43+D43+E43+F43)*(1+'1. Настройки'!$B$10/100) -> 26.265 | H43: =G43*B43 -> 105.06 | I43: =CEILING(G43*'1. Настройки'!$B$9+1,5)-1 -> 44 | J43: =I43-G43 -> 17.735 | K43: =J43*B43 -> 70.94 | L43: =IFERROR(J43/I43,0) -> 0.40306818
A45: Private Car with Driver (без билетов) | B45: 1 | C45: =('1. Настройки'!$B$6+0*'1. Настройки'!$B$7)/B45 -> 36 | D45: =SUMIFS('2. Билеты по остановкам'!$D$5:$D$56,'2. Билеты по остановкам'!$A$5:$A$56,$A$45,'2. Билеты по остановкам'!$E$5:$E$56,"билет") -> 0 | E45: =SUMIFS('2. Билеты по остановкам'!$D$5:$D$56,'2. Билеты по остановкам'!$A$5:$A$56,$A$45,'2. Билеты по остановкам'!$E$5:$E$56,"доп") -> 0 | F45: ='1. Настройки'!$B$8 -> 1.5 | G45: =(C45+D45+E45+F45)*(1+'1. Настройки'!$B$10/100) -> 38.625 | H45: =G45*B45 -> 38.625 | I45: =CEILING(G45*'1. Настройки'!$B$9+1,5)-1 -> 64 | J45: =I45-G45 -> 25.375 | K45: =J45*B45 -> 25.375 | L45: =IFERROR(J45/I45,0) -> 0.39648438
B46: 2 | C46: =('1. Настройки'!$B$6+0*'1. Настройки'!$B$7)/B46 -> 18 | D46: =SUMIFS('2. Билеты по остановкам'!$D$5:$D$56,'2. Билеты по остановкам'!$A$5:$A$56,$A$45,'2. Билеты по остановкам'!$E$5:$E$56,"билет") -> 0 | E46: =SUMIFS('2. Билеты по остановкам'!$D$5:$D$56,'2. Билеты по остановкам'!$A$5:$A$56,$A$45,'2. Билеты по остановкам'!$E$5:$E$56,"доп") -> 0 | F46: ='1. Настройки'!$B$8 -> 1.5 | G46: =(C46+D46+E46+F46)*(1+'1. Настройки'!$B$10/100) -> 20.085 | H46: =G46*B46 -> 40.17 | I46: =CEILING(G46*'1. Настройки'!$B$9+1,5)-1 -> 34 | J46: =I46-G46 -> 13.915 | K46: =J46*B46 -> 27.83 | L46: =IFERROR(J46/I46,0) -> 0.40926471
B47: 3 | C47: =('1. Настройки'!$B$6+0*'1. Настройки'!$B$7)/B47 -> 12 | D47: =SUMIFS('2. Билеты по остановкам'!$D$5:$D$56,'2. Билеты по остановкам'!$A$5:$A$56,$A$45,'2. Билеты по остановкам'!$E$5:$E$56,"билет") -> 0 | E47: =SUMIFS('2. Билеты по остановкам'!$D$5:$D$56,'2. Билеты по остановкам'!$A$5:$A$56,$A$45,'2. Билеты по остановкам'!$E$5:$E$56,"доп") -> 0 | F47: ='1. Настройки'!$B$8 -> 1.5 | G47: =(C47+D47+E47+F47)*(1+'1. Настройки'!$B$10/100) -> 13.905 | H47: =G47*B47 -> 41.715 | I47: =CEILING(G47*'1. Настройки'!$B$9+1,5)-1 -> 24 | J47: =I47-G47 -> 10.095 | K47: =J47*B47 -> 30.285 | L47: =IFERROR(J47/I47,0) -> 0.420625
B48: 4 | C48: =('1. Настройки'!$B$6+0*'1. Настройки'!$B$7)/B48 -> 9 | D48: =SUMIFS('2. Билеты по остановкам'!$D$5:$D$56,'2. Билеты по остановкам'!$A$5:$A$56,$A$45,'2. Билеты по остановкам'!$E$5:$E$56,"билет") -> 0 | E48: =SUMIFS('2. Билеты по остановкам'!$D$5:$D$56,'2. Билеты по остановкам'!$A$5:$A$56,$A$45,'2. Билеты по остановкам'!$E$5:$E$56,"доп") -> 0 | F48: ='1. Настройки'!$B$8 -> 1.5 | G48: =(C48+D48+E48+F48)*(1+'1. Настройки'!$B$10/100) -> 10.815 | H48: =G48*B48 -> 43.26 | I48: =CEILING(G48*'1. Настройки'!$B$9+1,5)-1 -> 19 | J48: =I48-G48 -> 8.185 | K48: =J48*B48 -> 32.74 | L48: =IFERROR(J48/I48,0) -> 0.43078947
A51: Серая строка «1 человек» — не для продажи, а чтобы ты видел, где ты уходишь в ноль на соло-туристе.
...

Sheet 4. Ценники на сайт
A1: ГОТОВЫЕ ЦЕННИКИ — что ставить на страницы туров
A2: Колонка «From $X» — цена за человека при 4 пассажирах. Это и есть строка From на сайте.
A4: Тур | B4: Сейчас на сайте | C4: Единица сейчас | D4: ПОЛ (мин. цена при 4 чел) | E4: СТАВЬ From $X | F4: Цена за 1 (2 чел) | G4: Цена за 1 (3 чел) | H4: Прибыль с выезда при 4 чел | I4: Вердикт | J4: Что не так сейчас
A5: Ubud Highlights Tour | B5: 70 | C5: с человека | D5: ='3. Цена на 1-2-3-4 чел'!I8 -> 69 | E5: 69 | F5: ='3. Цена на 1-2-3-4 чел'!I6 -> 84 | G5: ='3. Цена на 1-2-3-4 чел'!I7 -> 74 | H5: ='3. Цена на 1-2-3-4 чел'!K8 -> 105.2775 | I5: ОСТАВЬ. Пол $69, ты продаёшь за $70 — попал точно. | J5: Обед в Кинтамани включён, а в цене его часто забывают. Обезьяний лес 130k — самый дорогой билет дня. Билеты + обед = $31 с человека.
A6: Ubud Instagram Tour | B6: 75 | C6: с человека | D6: ='3. Цена на 1-2-3-4 чел'!I13 -> 89 | E6: 89 | F6: ='3. Цена на 1-2-3-4 чел'!I11 -> 104 | G6: ='3. Цена на 1-2-3-4 чел'!I12 -> 94 | H6: ='3. Цена на 1-2-3-4 чел'!K13 -> 141.5025 | I6: ПОДНИМИ до $89 ИЛИ убери качели из «включено» (тогда пол $74). | J6: КРИТИЧНО: на странице заявлены включёнными качели Tegalalang (250–400k). Это дороже всех остальных билетов вместе. При 1–2 гостях ты на $75 уходишь В МИНУС.
A7: Bali UNESCO Heritage Tour | B7: 70 | C7: с человека | D7: ='3. Цена на 1-2-3-4 чел'!I18 -> 59 | E7: 69 | F7: ='3. Цена на 1-2-3-4 чел'!I16 -> 74 | G7: ='3. Цена на 1-2-3-4 чел'!I17 -> 64 | H7: ='3. Цена на 1-2-3-4 чел'!K18 -> 97.465 | I7: НЕ СНИЖАЙ. Пол $59, но $70 у тебя уже покупают. Забирай маржу. | J7: Почти тот же маршрут, что Tanah Lot & Bedugul, но продаётся с человека, а тот — за машину. Один из двух ценников точно неверный.
A8: Tanah Lot & Bedugul Tour | B8: 65 | C8: за машину | D8: ='3. Цена на 1-2-3-4 чел'!I23 -> 59 | E8: 59 | F8: ='3. Цена на 1-2-3-4 чел'!I21 -> 74 | G8: ='3. Цена на 1-2-3-4 чел'!I22 -> 64 | H8: ='3. Цена на 1-2-3-4 чел'!K23 -> 94.89 | I8: ПЕРЕВЕДИ на цену с человека, билеты включи. | J8: Продаётся «за машину» и БЕЗ билетов. Клиент доплатит ~$24 с носа на месте. Это ровно то ощущение развода, от которого ты отстраиваешься.
A9: East Bali Instagram Tour | B9: 65 | C9: за машину | D9: ='3. Цена на 1-2-3-4 чел'!I28 -> 64 | E9: 69 | F9: ='3. Цена на 1-2-3-4 чел'!I26 -> 79 | G9: ='3. Цена на 1-2-3-4 чел'!I27 -> 69 | H9: ='3. Цена на 1-2-3-4 чел'!K28 -> 100.7275 | I9: ПЕРЕВЕДИ на цену с человека. Пол $64, ставь $69 — билеты самые дорогие. | J9: Самый дорогой тур по билетам во всём каталоге ($27), а продаётся «за машину» без билетов. Хуже всего по восприятию.
A10: Bali Instagram Highlights Tour | B10: 65 | C10: за машину | D10: ='3. Цена на 1-2-3-4 чел'!I33 -> 69 | E10: 69 | F10: ='3. Цена на 1-2-3-4 чел'!I31 -> 84 | G10: ='3. Цена на 1-2-3-4 чел'!I32 -> 74 | H10: ='3. Цена на 1-2-3-4 чел'!K33 -> 115.5775 | I10: СНАЧАЛА почини маршрут, потом ставь $69 с человека. | J10: Маршрут Бедугул + Лемпуянг — это разные концы острова, ~250 км. В 10 часов не влезет. Либо разбей на два тура, либо закладывай 12 ч и переработку.
A11: North Bali & Lovina Dolphins | B11: 80 | C11: с человека | D11: ='3. Цена на 1-2-3-4 чел'!I38 -> 49 | E11: 79 | F11: ='3. Цена на 1-2-3-4 чел'!I36 -> 64 | G11: ='3. Цена на 1-2-3-4 чел'!I37 -> 54 | H11: ='3. Цена на 1-2-3-4 чел'!K38 -> 85.79 | I11: НЕ СНИЖАЙ. Пол $49, продаёшь за $80. Самая жирная маржа в каталоге. | J11: 10–12 часов = переработка водителя. Старт ~3 утра, уточни доплату за ночной выезд.
A12: Lovina Dolphin Sunrise Tour | B12: 75 | C12: с человека | D12: ='3. Цена на 1-2-3-4 чел'!I43 -> 44 | E12: 69 | F12: ='3. Цена на 1-2-3-4 чел'!I41 -> 59 | G12: ='3. Цена на 1-2-3-4 чел'!I42 -> 49 | H12: ='3. Цена на 1-2-3-4 чел'!K43 -> 70.94 | I12: НЕ СНИЖАЙ сильно. Пол $44, продаёшь $75. Ставь $69. | J12: Выезд в 03:00. Уточни у водителя доплату за ночной старт — её почти всегда берут.
A13: Private Car with Driver (без билетов) | B13: — | C13: за машину | D13: ='3. Цена на 1-2-3-4 чел'!I48 -> 19 | E13: 59 | F13: ='3. Цена на 1-2-3-4 чел'!I46 -> 34 | G13: ='3. Цена на 1-2-3-4 чел'!I47 -> 24 | H13: ='3. Цена на 1-2-3-4 чел'!K48 -> 32.74 | I13: $59 ЗА МАШИНУ до 4 чел (не с человека). Пол $37/машина. | J13: Единственный тур, который правильно продавать ЗА МАШИНУ, а не с человека. Билеты клиент платит сам — так и надо, просто напиши это явно.
A15: ПОЛ ≠ ЦЕНА. Расчёт показывает, ниже чего опускаться нельзя. Если рынок уже платит больше — не снижай.
A16: Колонки «2 чел» и «3 чел» — это тоже пол. К ним применяй ту же логику: не ниже пола, но и не ниже текущей цены, если она работает.
A18: ТЕКСТ НА СТРАНИЦУ ТУРА — копируй как есть
A19: From $X per person (4 travellers sharing a private car)
A21: Private car, English-speaking driver, hotel pickup and drop-off.
A22: All entrance fees included. No extra payments during the tour.
A24: 1 traveller — $A per person
A25: 2 travellers — $B per person
A26: 3 travellers — $C per person
A27: 4 travellers — $D per person
A29: A, B, C, D — из таблицы выше. Показывай всю лестницу, а не только From.

Sheet 5. Водитель vs поставщик
A1: СВОЙ ВОДИТЕЛЬ ИЛИ ПОСТАВЩИК ЗА $45 С ЧЕЛОВЕКА?
A2: Поставщик берёт фикс с человека. Свой водитель — фикс с машины. Точка перелома у каждого тура своя.
A4: Цена поставщика, $ с человека (из твоего teardown) | B4: 45
A6: Тур | B6: Свой водитель 1 чел | C6: 2 чел | D6: 3 чел | E6: 4 чел | F6: Выгода своим водителем при 4 чел, на выезд | G6: С какого числа людей выгодно
A7: Ubud Highlights Tour | B7: ='3. Цена на 1-2-3-4 чел'!G5 -> 70.490625 | C7: ='3. Цена на 1-2-3-4 чел'!G6 -> 51.950625 | D7: ='3. Цена на 1-2-3-4 чел'!G7 -> 45.770625 | E7: ='3. Цена на 1-2-3-4 чел'!G8 -> 42.680625 | F7: =('5. Водитель vs поставщик'!$B$4-E7)*4 -> 9.2775 | G7: =IF(B7<'5. Водитель vs поставщик'!$B$4,"с 1",IF(C7<'5. Водитель vs поставщик'!$B$4,"с 2",IF(D7<'5. Водитель vs поставщик'!$B$4,"с 3",IF(E7<'5. Водитель vs поставщик'!$B$4,"с 4","никогда")))) -> с 4
A8: Ubud Instagram Tour | B8: ='3. Цена на 1-2-3-4 чел'!G10 -> 81.434375 | C8: ='3. Цена на 1-2-3-4 чел'!G11 -> 62.894375 | D8: ='3. Цена на 1-2-3-4 чел'!G12 -> 56.714375 | E8: ='3. Цена на 1-2-3-4 чел'!G13 -> 53.624375 | F8: =('5. Водитель vs поставщик'!$B$4-E8)*4 -> -34.4975 | G8: =IF(B8<'5. Водитель vs поставщик'!$B$4,"с 1",IF(C8<'5. Водитель vs поставщик'!$B$4,"с 2",IF(D8<'5. Водитель vs поставщик'!$B$4,"с 3",IF(E8<'5. Водитель vs поставщик'!$B$4,"с 4","никогда")))) -> никогда
A9: Bali UNESCO Heritage Tour | B9: ='3. Цена на 1-2-3-4 чел'!G15 -> 62.44375 | C9: ='3. Цена на 1-2-3-4 чел'!G16 -> 43.90375 | D9: ='3. Цена на 1-2-3-4 чел'!G17 -> 37.72375 | E9: ='3. Цена на 1-2-3-4 чел'!G18 -> 34.63375 | F9: =('5. Водитель vs поставщик'!$B$4-E9)*4 -> 41.465 | G9: =IF(B9<'5. Водитель vs поставщик'!$B$4,"с 1",IF(C9<'5. Водитель vs поставщик'!$B$4,"с 2",IF(D9<'5. Водитель vs поставщик'!$B$4,"с 3",IF(E9<'5. Водитель vs поставщик'!$B$4,"с 4","никогда")))) -> с 2
A10: Tanah Lot & Bedugul Tour | B10: ='3. Цена на 1-2-3-4 чел'!G20 -> 63.0875 | C10: ='3. Цена на 1-2-3-4 чел'!G21 -> 44.5475 | D10: ='3. Цена на 1-2-3-4 чел'!G22 -> 38.3675 | E10: ='3. Цена на 1-2-3-4 чел'!G23 -> 35.2775 | F10: =('5. Водитель vs поставщик'!$B$4-E10)*4 -> 38.89 | G10: =IF(B10<'5. Водитель vs поставщик'!$B$4,"с 1",IF(C10<'5. Водитель vs поставщик'!$B$4,"с 2",IF(D10<'5. Водитель vs поставщик'!$B$4,"с 3",IF(E10<'5. Водитель vs поставщик'!$B$4,"с 4","никогда")))) -> с 2
A11: East Bali Instagram Tour | B11: ='3. Цена на 1-2-3-4 чел'!G25 -> 66.628125 | C11: ='3. Цена на 1-2-3-4 чел'!G26 -> 48.088125 | D11: ='3. Цена на 1-2-3-4 чел'!G27 -> 41.908125 | E11: ='3. Цена на 1-2-3-4 чел'!G28 -> 38.818125 | F11: =('5. Водитель vs поставщик'!$B$4-E11)*4 -> 24.7275 | G11: =IF(B11<'5. Водитель vs поставщик'!$B$4,"с 1",IF(C11<'5. Водитель vs поставщик'!$B$4,"с 2",IF(D11<'5. Водитель vs поставщик'!$B$4,"с 3",IF(E11<'5. Водитель vs поставщик'!$B$4,"с 4","никогда")))) -> с 3
A12: Bali Instagram Highlights Tour | B12: ='3. Цена на 1-2-3-4 чел'!G30 -> 75.640625 | C12: ='3. Цена на 1-2-3-4 чел'!G31 -> 51.950625 | D12: ='3. Цена на 1-2-3-4 чел'!G32 -> 44.053958 | E12: ='3. Цена на 1-2-3-4 чел'!G33 -> 40.105625 | F12: =('5. Водитель vs поставщик'!$B$4-E12)*4 -> 19.5775 | G12: =IF(B12<'5. Водитель vs поставщик'!$B$4,"с 1",IF(C12<'5. Водитель vs поставщик'!$B$4,"с 2",IF(D12<'5. Водитель vs поставщик'!$B$4,"с 3",IF(E12<'5. Водитель vs поставщик'!$B$4,"с 4","никогда")))) -> с 3
A13: North Bali & Lovina Dolphins | B13: ='3. Цена на 1-2-3-4 чел'!G35 -> 63.0875 | C13: ='3. Цена на 1-2-3-4 чел'!G36 -> 39.3975 | D13: ='3. Цена на 1-2-3-4 чел'!G37 -> 31.500833 | E13: ='3. Цена на 1-2-3-4 чел'!G38 -> 27.5525 | F13: =('5. Водитель vs поставщик'!$B$4-E13)*4 -> 69.79 | G13: =IF(B13<'5. Водитель vs поставщик'!$B$4,"с 1",IF(C13<'5. Водитель vs поставщик'!$B$4,"с 2",IF(D13<'5. Водитель vs поставщик'!$B$4,"с 3",IF(E13<'5. Водитель vs поставщик'!$B$4,"с 4","никогда")))) -> с 2
A14: Lovina Dolphin Sunrise Tour | B14: ='3. Цена на 1-2-3-4 чел'!G40 -> 54.075 | C14: ='3. Цена на 1-2-3-4 чел'!G41 -> 35.535 | D14: ='3. Цена на 1-2-3-4 чел'!G42 -> 29.355 | E14: ='3. Цена на 1-2-3-4 чел'!G43 -> 26.265 | F14: =('5. Водитель vs поставщик'!$B$4-E14)*4 -> 74.94 | G14: =IF(B14<'5. Водитель vs поставщик'!$B$4,"с 1",IF(C14<'5. Водитель vs поставщик'!$B$4,"с 2",IF(D14<'5. Водитель vs поставщик'!$B$4,"с 3",IF(E14<'5. Водитель vs поставщик'!$B$4,"с 4","никогда")))) -> с 2
A16: КАК ЭТО ЧИТАТЬ
A17: Поставщик за $45 с человека — это НЕ грабёж, как казалось раньше. В $45 у него сидят билеты и обед,
A18: а на маленькой группе он на тебе почти не зарабатывает: на двоих в Ubud Highlights он в минусе.
A20: Вывод: держи оба канала. Соло и пары — отдавай поставщику, там его цена лучше твоей себестоимости.
A21: Группы от 3 человек — вози своим водителем, там вся выгода. Не разрывай отношения с поставщиком,
A22: он твоя страховка на маленькие заказы и на дни, когда твой водитель занят.

Sheet 6. Источники
A1: ОТКУДА ЦИФРЫ И ЧТО НАДО ПРОВЕРИТЬ САМОМУ
A3: Что | B3: Деталь | C3: Источник
A4: Маршруты туров (какие остановки) | B4: Твои же страницы туров, блок «Key stops» и «What's included» | C4: Файлы bali-tour-*.html на твоём маке, август 2026
A5: Входные билеты 2026 | B5: Complete List of Bali Entrance Fees 2026 | C5: baliholidaysecrets.com/bali-entrance-fees/
A6: Подорожание Танах Лот и Улун Дану | B6: Танах Лот 75k→100k с 01.04.2026; Улун Дану 75k→100k с 01.07.2026 | C6: heybali.info — новость о повышении цен
A7: Лемпуянг: билет + обязательный шаттл | B7: 100k билет + 50k шаттл, машину выше терминала не пускают | C7: baliholidaysecrets.com/lempuyang-temple/
A8: Gunung Kawi Sebatu — 50k, саронг включён | B8: Подтверждено | C8: baliholidaysecrets.com/pura-gunung-kawi-sebatu/
A9: Kintamani — 50k с иностранца | B9: Официальный сбор, домашним 25k | C9: thebalisun.com — разъяснение по сборам в Кинтамани
A10: Lahangan Sweet — 100k, шаттл включён | B10: Дороже, чем кажется: это не бесплатная смотровая | C10: lifetravelandasia.com/lahangan-sweet-guide/
A11: Лодка на дельфинов в Ловине | B11: Сборная 100k с человека; приватная 400k за лодку до 3 чел, +50k за человека | C11: lovinatours.com/lovina-dolphin-watching-tour/
A12: Обед-буфет в Кинтамани — 125k | B12: ОЦЕНКА, не подтверждено. Спроси у водителя реальную цену в его ресторане. | C12: допущение
A13: Качели Tegalalang — 250k | B13: Взята нижняя граница диапазона 250–400k. Если качели премиум — будет дороже. | C13: baliholidaysecrets.com
A14: Batukaru | B14: В маршрутах твоих туров не встретился — из расчёта убран. | C14: —
A16: ПРОВЕРЬ ДО ПЕРВОЙ ПРОДАЖИ
A17: 1. Входит ли в $36 бензин, парковки и еда водителя. Если нет — добавь ~50k IDR/день в «мелочь».
A18: 2. Доплата за старт в 03:00–04:00 (Ловина, Батур). Её берут почти всегда.
A19: 3. Ставка за час переработки. Сейчас в расчёте $5/час — подставь реальную.
A20: 4. Реальная цена обеда в Кинтамани у твоего водителя — у них свои рестораны и своя цена.
A21: 5. Какого класса качели включены в Ubud Instagram Tour. Разброс 250–400k, это $9 разницы с человека.
A22: 6. Курс рупии. Пересчитывай раз в квартал — билеты в 2026 уже дорожали дважды.
